Workbook

Sheet Full Data
A1: SEARCHED | B1: SUMMARY | E1: ---------------------------------------------------------------------------------EXPORTS (LINKED TO EXPORT SHEET--------------------------------------------------------------------------------- | L1: COMPARE | M1: IMPORTED | N1: PUBCHEM | O1: SDS SHEET | P1: HAZARDS | Q1: PICTOGRAMS | R1: PICTOGRAM CODES
A2: (-) Borneol (NFPA Class IIIA) | B2: STATUS CODE: | C2: ✅✅ Extremely Confident | D2: -----------> | E2: NAME: | F2: L(-)-Borneol | G2: HAZARDS: | H2: Flammable solid May form combustible dust concentrations in air Causes skin irritation Causes serious eye irritation | I2: UNITS | J2: g | K2: <----------- | L2: NAME: | M2: (-) Borneol (NFPA Class IIIA) | N2: (-)-Borneol | O2: L(-)-Borneol | P2: Flammable solid May form combustible dust concentrations in air Causes skin irritation Causes serious eye irritation | Q2: Flammable Irritant | R2: FL, IR
B3: CONFIDENCE SCORE: | C3: 100 | D3: -----------> | E3: SYNONYMS: | F3: endo-(1S)-1,7,7-Trimethylbicyclo[2.2.1]heptan-2-ol | I3: QUANTITY | J3: 50 | K3: <----------- | L3: CAS NO.: | M3: 464-45-9 | N3: 464-45-9 507-70-0 | O3: 464-45-9
B4: CONF. SCORE INFO: | D4: -----------> | E4: SUPPLIER | F4: Aldrich | G4: PICTOGRAM CODES: | H4: FL, IR | I4: STORAGE NOTES | J4: Keep containers tightly closed in a dry, cool and well-ventilated place. Keep away from heat, sparks and flame. Flammables area. Incompatible Materials. Strong oxidizing agents. | K4: <----------- | L4: SYNONYMS: | N4: L-Borneol Linderol NGAI camphor l-2-Camphanol Borneol, (-)- | O4: endo-(1S)-1,7,7-Trimethylbicyclo[2.2.1]heptan-2-ol
A5: 464-45-9 | D5: -----------> | E5: CAS NO: | F5: 464-45-9 | G5: SDS LINK: | H5: https://www.fishersci.com/store/msds?partNumber=AC160650250&productDescription=l-borneol-gr&vendorId=VN00032119&keyword=true&countryCode=US&language=en | K5: <----------- | L5: FORMULA: | N5: C10H18O | O5: C10H18O | P5: H228 (99%): Flammable solid [Danger Flammable solids] H315 (30.4%): Causes skin irritation [Warning Skin corrosion/irritation] H317 (23.6%): May cause an allergic skin reaction [Warning Sensitization, Skin] H371: May cause damage to organs [Warning Specific target organ toxicity, single exposure] Not Classified | Q5: Flammable Irritant Health Hazard | R5: FL, IR, CA
D6: -----------> | E6: CLASS: | F6: Organic compound | G6: LOCATION: | H6: 6-144 | I6: FORMULA | J6: C10H18O | K6: <----------- | L6: MW: | N6: 154.25 | O6: 154.25
B7: ERRORS: | D7: -----------> | E7: SIGNAL WORD: | F7: Danger | G7: SHELF: | H7: B-3 | I7: SDS REV. DATE: | J7: 24-Dec-2021 | K7: <----------- | L7: SIGNAL WORD: | N7: Danger | O7: Danger
A9: (-) Carvone (Fp 190.4 deg F) | B9: STATUS CODE: | C9: ✅✅ Extremely Confident | D9: -----------> | E9: NAME: | F9: L(-)-Carvone | G9: HAZARDS: | H9: Combustible liquid May cause an allergic skin reaction | I9: UNITS | J9: mL | K9: <----------- | L9: NAME: | M9: (-) Carvone (Fp 190.4 deg F) | N9: (-)-Carvone | O9: L(-)-Carvone | P9: Combustible liquid May cause an allergic skin reaction | Q9: Flammable | R9: FL
B10: CONFIDENCE SCORE: | C10: 100 | D10: -----------> | E10: SYNONYMS: | F10: (R)-(-)-p-Mentha-6,8-dien-2-one | I10: QUANTITY | J10: 15 | K10: <----------- | L10: CAS NO.: | M10: 6485-40-1 | N10: 6485-40-1 | O10: 6485-40-1
B11: CONF. SCORE INFO: | D11: -----------> | E11: SUPPLIER | F11: Fluka | G11: PICTOGRAM CODES: | H11: FL | I11: STORAGE NOTES | J11: Keep containers tightly closed in a dry, cool and well-ventilated place. Keep away from heat, sparks and flame. Incompatible Materials. Strong oxidizing agents. Strong acids. Strong bases. | K11: <----------- | L11: SYNONYMS: | N11: (R)-(-)-Carvone l-Carvone L(-)-Carvone (R)-Carvone Levo-carvone | O11: (R)-(-)-p-Mentha-6,8-dien-2-one
A12: 6485-40-1 | D12: -----------> | E12: CAS NO: | F12: 6485-40-1 | G12: SDS LINK: | H12: https://www.fishersci.com/store/msds?partNumber=AC154591000&productDescription=l-carvone-gr&vendorId=VN00032119&keyword=true&countryCode=US&language=en | K12: <----------- | L12: FORMULA: | N12: C10H14O | O12: C10H14O | P12: H317: May cause an allergic skin reaction [Warning Sensitization, Skin] H302 (79.8%): Harmful if swallowed [Warning Acute toxicity, oral] H227: Combustible liquid [Warning Flammable liquids] | Q12: Irritant | R12: IR
D13: -----------> | E13: CLASS: | F13: Organic compound | G13: LOCATION: | H13: 6-144 | I13: FORMULA | J13: C10H14O | K13: <----------- | L13: MW: | N13: 150.22 | O13: 150.22
B14: ERRORS: | D14: -----------> | E14: SIGNAL WORD: | F14: Warning | G14: SHELF: | H14: B-3 | I14: SDS REV. DATE: | J14: 24-Dec-2021 | K14: <----------- | L14: SIGNAL WORD: | N14: Warning | O14: Warning
A16: (+) Carvone (Fp 190.4 deg F) | B16: STATUS CODE: | C16: ✅✅ Extremely Confident | D16: -----------> | E16: NAME: | F16: D(+)-Carvone | G16: HAZARDS: | H16: May cause an allergic skin reaction | I16: UNITS | J16: mL | K16: <----------- | L16: NAME: | M16: (+) Carvone (Fp 190.4 deg F) | N16: d-Carvone | O16: D(+)-Carvone | P16: May cause an allergic skin reaction | Q16: Not Found | R16: Not Found
B17: CONFIDENCE SCORE: | C17: 100 | D17: -----------> | E17: SYNONYMS: | F17: (S)-(+)-p-Mentha-6,8-dien-2-one | I17: QUANTITY | J17: 15 | K17: <----------- | L17: CAS NO.: | M17: 2244-16-8 | N17: 2244-16-8 | O17: 2244-16-8
B18: CONF. SCORE INFO: | D18: -----------> | E18: SUPPLIER | F18: Fluka | G18: PICTOGRAM CODES: | H18: Not Found | I18: STORAGE NOTES | J18: Keep containers tightly closed in a dry, cool and well-ventilated place. Store under an inert atmosphere. Protect from light. Incompatible Materials. Strong oxidizing agents. Strong reducing agents. | K18: <----------- | L18: SYNONYMS: | N18: (S)-(+)-Carvone (+)-Carvone (S)-Carvone Carvone, (+)- (+)-(S)-Carvone | O18: (S)-(+)-p-Mentha-6,8-dien-2-one
A19: 2244-16-8 | D19: -----------> | E19: CAS NO: | F19: 2244-16-8 | G19: SDS LINK: | H19: https://www.fishersci.com/store/msds?partNumber=AC377841000&productDescription=d-carvone-synth-ml&vendorId=VN00032119&keyword=true&countryCode=US&language=en | K19: <----------- | L19: FORMULA: | N19: C10H14O | O19: C10H14O | P19: H317: May cause an allergic skin reaction [Warning Sensitization, Skin] H302 (16.3%): Harmful if swallowed [Warning Acute toxicity, oral] | Q19: Irritant | R19: IR
D20: -----------> | E20: CLASS: | F20: Organic compound | G20: LOCATION: | H20: 6-144 | I20: FORMULA | J20: C10H14O | K20: <----------- | L20: MW: | N20: 150.22 | O20: 150.22
B21: ERRORS: | C21: Error, could not identify pictograms from SDS hazard statements | D21: -----------> | E21: SIGNAL WORD: | F21: Warning | G21: SHELF: | H21: B-3 | I21: SDS REV. DATE: | J21: 25-Dec-2021 | K21: <----------- | L21: SIGNAL WORD: | N21: Warning | O21: Warning
A23: 1, 10-Phenanthroline monohydrate | B23: STATUS CODE: | C23: ✅✅ Extremely Confident | D23: -----------> | E23: NAME: | F23: 1,10-Phenanthroline monohydrate | G23: HAZARDS: | H23: Toxic if swallowed Acute oral toxicity | I23: UNITS | J23: g | K23: <----------- | L23: NAME: | M23: 1, 10-Phenanthroline monohydrate | N23: 1,10-Phenanthroline hydrate | O23: 1,10-Phenanthroline monohydrate | P23: Toxic if swallowed Acute oral toxicity | Q23: Acute Toxicity | R23: AC
B24: CONFIDENCE SCORE: | C24: 95 | D24: -----------> | E24: SYNONYMS: | F24: o-Phenanthroline monohydrate | I24: QUANTITY | J24: 5 | K24: <----------- | L24: CAS NO.: | M24: 5144-89-8 | N24: 5144-89-8 | O24: 5144-89-8
B25: CONF. SCORE INFO: | C25: Chemical Names (normalized) do not match SDS: 1 10 phenanthroline monohydrate PubChem: 1 10 phenanthroline hydrate Penalty: -5 | D25: -----------> | E25: SUPPLIER | F25: Kodak | G25: PICTOGRAM CODES: | H25: AC | I25: STORAGE NOTES | J25: Keep containers tightly closed in a dry, cool and well-ventilated place. Keep under nitrogen. Incompatible Materials. Strong oxidizing agents. Strong acids. | K25: <----------- | L25: SYNONYMS: | N25: RefChem:855306 1,10-Phenanthroline monohydrate o-Phenanthroline monohydrate MFCD00149973 phenanthroline monohydrate | O25: o-Phenanthroline monohydrate
A26: 5144-89-8 | D26: -----------> | E26: CAS NO: | F26: 5144-89-8 | G26: SDS LINK: | H26: https://www.fishersci.com/store/msds?partNumber=AA3091009&productDescription=phenanthroline-acs-g&vendorId=VN00024248&keyword=true&countryCode=US&language=en | K26: <----------- | L26: FORMULA: | N26: C12H8N2.H2O | O26: C12H8N2.H2O | P26: H301 (100%): Toxic if swallowed [Danger Acute toxicity, oral] H400 (96.7%): Very toxic to aquatic life [Warning Hazardous to the aquatic environment, acute hazard] H410 (99.2%): Very toxic to aquatic life with long lasting effects [Warning Hazardous to the aquatic environment, long-term hazard] | Q26: Acute Toxic Environmental Hazard | R26: AC, EN
D27: -----------> | E27: CLASS: | F27: Organic compound | G27: LOCATION: | H27: 6-144 | I27: FORMULA | J27: C12H8N2.H2O | K27: <----------- | L27: MW: | N27: 198.22 | O27: 198.23
B28: ERRORS: | D28: -----------> | E28: SIGNAL WORD: | F28: Danger | G28: SHELF: | H28: B-5 | I28: SDS REV. DATE: | J28: 29-Mar-2024 | K28: <----------- | L28: SIGNAL WORD: | N28: Danger | O28: Danger
A30: 1, 10-Phenanthroline monohydrochloride monohydrate | B30: STATUS CODE: | C30: ❌ Fail | D30: -----------> | E30: NAME: | F30: 1,10-Phenanthroline monohydrochloride monohydrate | G30: HAZARDS: | H30: Toxic if swallowed | I30: UNITS | J30: g | K30: <----------- | L30: NAME: | M30: 1, 10-Phenanthroline monohydrochloride monohydrate | N30: 1,10-Phenanthroline hydrochloride | O30: 1,10-Phenanthroline monohydrochloride monohydrate | P30: Toxic if swallowed | Q30: Acute Toxicity | R30: AC
B31: CONFIDENCE SCORE: | C31: 25 | D31: -----------> | E31: SYNONYMS: | F31: No information available | I31: QUANTITY | J31: 5 | K31: <----------- | L31: CAS NO.: | M31: 3829-86-5 | N31: 22802-96-6 3829-86-5 | O31: 18851-33-7
B32: CONF. SCORE INFO: | C32: SDS CAS number does not match seached CAS OR a PubChem CAS number SDS: 18851-33-7 PubChem: 22802-96-6,3829-86-5 Penalty: -40 ──────────────────── Chemical Names (normalized) do not match SDS: 1 10 phenanthroline monohydrochloride monohydrate PubChem: 1 10 phenanthroline hydrochloride Penalty: -5 ──────────────────── Molecular Formulas (normalized) do not match SDS: C12H8N2.HCL.H2O PubChem: C12H9CLN2 Penalty: -10 ──────────────────── Molecular Weight NOT within +/- 1 g/mol SDS: 234.69 PubChem: 216.66 Penalty: -20 | D32: -----------> | E32: SUPPLIER | F32: J.T. Baker | G32: PICTOGRAM CODES: | H32: AC | I32: STORAGE NOTES | J32: Keep containers tightly closed in a dry, cool and well-ventilated place. Incompatible Materials. Strong oxidizing agents. Strong acids. Strong bases. | K32: <----------- | L32: SYNONYMS: | N32: 1,10-Phenanthroline, monohydrochloride Phenanthroline hydrochloride 1,10-Diazaphenanthrene hydrochloride 1,10-Phenanthroline, hydrochloride (1:1) NSC 4265 | O32: No information available
A33: 3829-86-5 | D33: -----------> | E33: CAS NO: | F33: 18851-33-7 | G33: SDS LINK: | H33: https://www.fishersci.com/store/msds?partNumber=AC130141000&productDescription=-phenanthroline-mono-gr&vendorId=VN00032119&keyword=true&countryCode=US&language=en | K33: <----------- | L33: FORMULA: | N33: C12H9ClN2 | O33: C12H8N2.HCl.H2O | P33: H301 (92.6%): Toxic if swallowed [Danger Acute toxicity, oral] H400 (94.4%): Very toxic to aquatic life [Warning Hazardous to the aquatic environment, acute hazard] H410 (94.4%): Very toxic to aquatic life with long lasting effects [Warning Hazardous to the aquatic environment, long-term hazard] | Q33: Acute Toxic Environmental Hazard | R33: AC, EN
D34: -----------> | E34: CLASS: | F34: Organic compound | G34: LOCATION: | H34: 6-144 | I34: FORMULA | J34: C12H8N2.HCl.H2O | K34: <----------- | L34: MW: | N34: 216.66 | O34: 234.69
B35: ERRORS: | D35: -----------> | E35: SIGNAL WORD: | F35: Danger | G35: SHELF: | H35: B-5 | I35: SDS REV. DATE: | J35: 24-Dec-2021 | K35: <----------- | L35: SIGNAL WORD: | N35: Danger | O35: Danger
A37: 1, 10-Phenanthroline monohydrochloride monohydrate | B37: STATUS CODE: | C37: ❌ Fail | D37: -----------> | E37: NAME: | F37: 1,10-Phenanthroline monohydrochloride monohydrate | G37: HAZARDS: | H37: Toxic if swallowed | I37: UNITS | J37: g | K37: <----------- | L37: NAME: | M37: 1, 10-Phenanthroline monohydrochloride monohydrate | N37: 1,10-Phenanthroline hydrochloride | O37: 1,10-Phenanthroline monohydrochloride monohydrate | P37: Toxic if swallowed | Q37: Acute Toxicity | R37: AC
B38: CONFIDENCE SCORE: | C38: 25 | D38: -----------> | E38: SYNONYMS: | F38: No information available | I38: QUANTITY | J38: 5 | K38: <----------- | L38: CAS NO.: | M38: 3829-86-5 | N38: 22802-96-6 3829-86-5 | O38: 18851-33-7
B39: CONF. SCORE INFO: | C39: SDS CAS number does not match seached CAS OR a PubChem CAS number SDS: 18851-33-7 PubChem: 22802-96-6,3829-86-5 Penalty: -40 ──────────────────── Chemical Names (normalized) do not match SDS: 1 10 phenanthroline monohydrochloride monohydrate PubChem: 1 10 phenanthroline hydrochloride Penalty: -5 ──────────────────── Molecular Formulas (normalized) do not match SDS: C12H8N2.HCL.H2O PubChem: C12H9CLN2 Penalty: -10 ──────────────────── Molecular Weight NOT within +/- 1 g/mol SDS: 234.69 PubChem: 216.66 Penalty: -20 | D39: -----------> | E39: SUPPLIER | F39: J.T. Baker | G39: PICTOGRAM CODES: | H39: AC | I39: STORAGE NOTES | J39: Keep containers tightly closed in a dry, cool and well-ventilated place. Incompatible Materials. Strong oxidizing agents. Strong acids. Strong bases. | K39: <----------- | L39: SYNONYMS: | N39: 1,10-Phenanthroline, monohydrochloride Phenanthroline hydrochloride 1,10-Diazaphenanthrene hydrochloride 1,10-Phenanthroline, hydrochloride (1:1) NSC 4265 | O39: No information available
A40: 3829-86-5 | D40: -----------> | E40: CAS NO: | F40: 18851-33-7 | G40: SDS LINK: | H40: https://www.fishersci.com/store/msds?partNumber=AC130141000&productDescription=-phenanthroline-mono-gr&vendorId=VN00032119&keyword=true&countryCode=US&language=en | K40: <----------- | L40: FORMULA: | N40: C12H9ClN2 | O40: C12H8N2.HCl.H2O | P40: H301 (92.6%): Toxic if swallowed [Danger Acute toxicity, oral] H400 (94.4%): Very toxic to aquatic life [Warning Hazardous to the aquatic environment, acute hazard] H410 (94.4%): Very toxic to aquatic life with long lasting effects [Warning Hazardous to the aquatic environment, long-term hazard] | Q40: Acute Toxic Environmental Hazard | R40: AC, EN
D41: -----------> | E41: CLASS: | F41: Organic compound | G41: LOCATION: | H41: 6-144 | I41: FORMULA | J41: C12H8N2.HCl.H2O | K41: <----------- | L41: MW: | N41: 216.66 | O41: 234.69
B42: ERRORS: | D42: -----------> | E42: SIGNAL WORD: | F42: Danger | G42: SHELF: | H42: B-5 | I42: SDS REV. DATE: | J42: 24-Dec-2021 | K42: <----------- | L42: SIGNAL WORD: | N42: Danger | O42: Danger
A44: 1,1,1 Trichloro 2 methyl propanol hemihydrate | B44: STATUS CODE: | C44: ✅ Pass | D44: -----------> | E44: NAME: | F44: 1,1,1-Trichloro-2-methyl-2-propanol hemihydrate | G44: HAZARDS: | H44: Harmful if swallowed Acute oral toxicity Causes skin irritation Causes serious eye irritation May cause respiratory irritation | I44: UNITS | J44: g | K44: <----------- | L44: NAME: | M44: 1,1,1 Trichloro 2 methyl propanol hemihydrate | N44: 1,1,1-Trichloro-2-methyl-2-propanol hemihydrate | O44: 1,1,1-Trichloro-2-methyl-2-propanol hemihydrate | P44: Harmful if swallowed Acute oral toxicity Causes skin irritation Causes serious eye irritation May cause respiratory irritation | Q44: Acute Toxicity Irritant | R44: AC, IR
B45: CONFIDENCE SCORE: | C45: 70 | D45: -----------> | E45: SYNONYMS: | F45: beta,beta,beta-Trichloro-tert-butyl alcohol | I45: QUANTITY | J45: 100 | K45: <----------- | L45: CAS NO.: | M45: 6001-64-5 | N45: 6001-64-5 | O45: 6001-64-5
B46: CONF. SCORE INFO: | C46: Molecular Formulas (normalized) do not match SDS: C4H7CL3O.0.5H2O PubChem: C8H16CL6O3 Penalty: -10 ──────────────────── Molecular Weight NOT within +/- 1 g/mol SDS: 186.47 PubChem: 372.9 Penalty: -20 | D46: -----------> | E46: SUPPLIER | F46: Eastman Kodak | G46: PICTOGRAM CODES: | H46: AC, IR | I46: STORAGE NOTES | J46: Keep in a dry, cool and well-ventilated place. Keep container tightly closed. Incompatible Materials. Acids. Strong oxidizing agents. Acid anhydrides. Acid chlorides. Metals. | K46: <----------- | L46: SYNONYMS: | N46: Chlorobutanol hemihydrate 3X4P6271OX 2-Propanol, 1,1,1-trichloro-2-methyl-, hydrate (2:1) CHLOROBUTANOL HEMIHYDRATE [II] 2-Propanol, 1,1,1-trichloro-2-methyl-, hemihydrate | O46: beta,beta,beta-Trichloro-tert-butyl alcohol
...

Sheet Success Report
A1: Summary and Success Report Date: 10/31/2025, 4:58:03 PM _______________________________ Runtime: 8minutes, 27.6seconds. _______________________________ Total Chemicals ran: 50 _______________________________ Successful SDS Sheets Total: 43 Percentage: 86% _______________________________ SDS Sheets that need review Total: 2 Percentage: 4% _______________________________ Failed SDS Sheets Total: 4 Percentage: 8% _______________________________ Errors encountered Total: 0 Percentage: 0%

Sheet Export
A1: ChemicalName | B1: Formula | C1: Synonyms | D1: CatalogCode | E1: CompanyName | F1: Grade | G1: Disposal | H1: CAS | I1: Class | J1: CompatibleFamily | K1: SignalWord | L1: HazardStatement | M1: GHSCodes | N1: SDSURL | O1: School | P1: StoreRoom | Q1: Shelf | R1: UOM | S1: LastUsed | T1: MinReorderAmount | U1: Amount | V1: Notes | W1: KitCatalog
A2: ='Full Data'!F2 -> L(-)-Borneol | B2: ='Full Data'!J6 -> C10H18O | C2: ='Full Data'!F3 -> endo-(1S)-1,7,7-Trimethylbicyclo[2.2.1]heptan-2-ol | E2: ='Full Data'!F4 -> Aldrich | H2: ='Full Data'!F5 -> 464-45-9 | I2: ='Full Data'!F6 -> Organic compound | K2: ='Full Data'!F7 -> Danger | L2: ='Full Data'!H2 -> Flammable solid May form combustible dust concentrations in air Causes skin irritation Causes serious eye irritation | M2: ='Full Data'!H4 -> FL, IR | N2: ='Full Data'!H5 -> https://www.fishersci.com/store/msds?partNumber=AC160650250&productDescription=l-borneol-gr&vendorId=VN00032119&keyword=true&countryCode=US&language=en | O2: CSCC TUNXIS | P2: ='Full Data'!H6 -> 6-144 | Q2: ='Full Data'!H7 -> B-3 | R2: ='Full Data'!J2 -> g | U2: ='Full Data'!J3 -> 50 | V2: ='Full Data'!J4 -> Keep containers tightly closed in a dry, cool and well-ventilated place. Keep away from heat, sparks and flame. Flammables area. Incompatible Materials. Strong oxidizing agents.
A3: ='Full Data'!F9 -> L(-)-Carvone | B3: ='Full Data'!J13 -> C10H14O | C3: ='Full Data'!F10 -> (R)-(-)-p-Mentha-6,8-dien-2-one | E3: ='Full Data'!F11 -> Fluka | H3: ='Full Data'!F12 -> 6485-40-1 | I3: ='Full Data'!F13 -> Organic compound | K3: ='Full Data'!F14 -> Warning | L3: ='Full Data'!H9 -> Combustible liquid May cause an allergic skin reaction | M3: ='Full Data'!H11 -> FL | N3: ='Full Data'!H12 -> https://www.fishersci.com/store/msds?partNumber=AC154591000&productDescription=l-carvone-gr&vendorId=VN00032119&keyword=true&countryCode=US&language=en | O3: CSCC TUNXIS | P3: ='Full Data'!H13 -> 6-144 | Q3: ='Full Data'!H14 -> B-3 | R3: ='Full Data'!J9 -> mL | U3: ='Full Data'!J10 -> 15 | V3: ='Full Data'!J11 -> Keep containers tightly closed in a dry, cool and well-ventilated place. Keep away from heat, sparks and flame. Incompatible Materials. Strong oxidizing agents. Strong acids. Strong bases.
A4: ='Full Data'!F16 -> D(+)-Carvone | B4: ='Full Data'!J20 -> C10H14O | C4: ='Full Data'!F17 -> (S)-(+)-p-Mentha-6,8-dien-2-one | E4: ='Full Data'!F18 -> Fluka | H4: ='Full Data'!F19 -> 2244-16-8 | I4: ='Full Data'!F20 -> Organic compound | K4: ='Full Data'!F21 -> Warning | L4: ='Full Data'!H16 -> May cause an allergic skin reaction | M4: ='Full Data'!H18 -> Not Found | N4: ='Full Data'!H19 -> https://www.fishersci.com/store/msds?partNumber=AC377841000&productDescription=d-carvone-synth-ml&vendorId=VN00032119&keyword=true&countryCode=US&language=en | O4: CSCC TUNXIS | P4: ='Full Data'!H20 -> 6-144 | Q4: ='Full Data'!H21 -> B-3 | R4: ='Full Data'!J16 -> mL | U4: ='Full Data'!J17 -> 15 | V4: ='Full Data'!J18 -> Keep containers tightly closed in a dry, cool and well-ventilated place. Store under an inert atmosphere. Protect from light. Incompatible Materials. Strong oxidizing agents. Strong reducing agents.
A5: ='Full Data'!F23 -> 1,10-Phenanthroline monohydrate | B5: ='Full Data'!J27 -> C12H8N2.H2O | C5: ='Full Data'!F24 -> o-Phenanthroline monohydrate | E5: ='Full Data'!F25 -> Kodak | H5: ='Full Data'!F26 -> 5144-89-8 | I5: ='Full Data'!F27 -> Organic compound | K5: ='Full Data'!F28 -> Danger | L5: ='Full Data'!H23 -> Toxic if swallowed Acute oral toxicity | M5: ='Full Data'!H25 -> AC | N5: ='Full Data'!H26 -> https://www.fishersci.com/store/msds?partNumber=AA3091009&productDescription=phenanthroline-acs-g&vendorId=VN00024248&keyword=true&countryCode=US&language=en | O5: CSCC TUNXIS | P5: ='Full Data'!H27 -> 6-144 | Q5: ='Full Data'!H28 -> B-5 | R5: ='Full Data'!J23 -> g | U5: ='Full Data'!J24 -> 5 | V5: ='Full Data'!J25 -> Keep containers tightly closed in a dry, cool and well-ventilated place. Keep under nitrogen. Incompatible Materials. Strong oxidizing agents. Strong acids.
A6: ='Full Data'!F30 -> 1,10-Phenanthroline monohydrochloride monohydrate | B6: ='Full Data'!J34 -> C12H8N2.HCl.H2O | C6: ='Full Data'!F31 -> No information available | E6: ='Full Data'!F32 -> J.T. Baker | H6: ='Full Data'!F33 -> 18851-33-7 | I6: ='Full Data'!F34 -> Organic compound | K6: ='Full Data'!F35 -> Danger | L6: ='Full Data'!H30 -> Toxic if swallowed | M6: ='Full Data'!H32 -> AC | N6: ='Full Data'!H33 -> https://www.fishersci.com/store/msds?partNumber=AC130141000&productDescription=-phenanthroline-mono-gr&vendorId=VN00032119&keyword=true&countryCode=US&language=en | O6: CSCC TUNXIS | P6: ='Full Data'!H34 -> 6-144 | Q6: ='Full Data'!H35 -> B-5 | R6: ='Full Data'!J30 -> g | U6: ='Full Data'!J31 -> 5 | V6: ='Full Data'!J32 -> Keep containers tightly closed in a dry, cool and well-ventilated place. Incompatible Materials. Strong oxidizing agents. Strong acids. Strong bases.
A7: ='Full Data'!F37 -> 1,10-Phenanthroline monohydrochloride monohydrate | B7: ='Full Data'!J41 -> C12H8N2.HCl.H2O | C7: ='Full Data'!F38 -> No information available | E7: ='Full Data'!F39 -> J.T. Baker | H7: ='Full Data'!F40 -> 18851-33-7 | I7: ='Full Data'!F41 -> Organic compound | K7: ='Full Data'!F42 -> Danger | L7: ='Full Data'!H37 -> Toxic if swallowed | M7: ='Full Data'!H39 -> AC | N7: ='Full Data'!H40 -> https://www.fishersci.com/store/msds?partNumber=AC130141000&productDescription=-phenanthroline-mono-gr&vendorId=VN00032119&keyword=true&countryCode=US&language=en | O7: CSCC TUNXIS | P7: ='Full Data'!H41 -> 6-144 | Q7: ='Full Data'!H42 -> B-5 | R7: ='Full Data'!J37 -> g | U7: ='Full Data'!J38 -> 5 | V7: ='Full Data'!J39 -> Keep containers tightly closed in a dry, cool and well-ventilated place. Incompatible Materials. Strong oxidizing agents. Strong acids. Strong bases.
A8: ='Full Data'!F44 -> 1,1,1-Trichloro-2-methyl-2-propanol hemihydrate | B8: ='Full Data'!J48 -> C4H7Cl3O.0.5H2O | C8: ='Full Data'!F45 -> beta,beta,beta-Trichloro-tert-butyl alcohol | E8: ='Full Data'!F46 -> Eastman Kodak | H8: ='Full Data'!F47 -> 6001-64-5 | I8: ='Full Data'!F48 -> Organic compound | K8: ='Full Data'!F49 -> Warning | L8: ='Full Data'!H44 -> Harmful if swallowed Acute oral toxicity Causes skin irritation Causes serious eye irritation May cause respiratory irritation | M8: ='Full Data'!H46 -> AC, IR | N8: ='Full Data'!H47 -> https://www.fishersci.com/store/msds?partNumber=AAA1018122&productDescription=trichlromethlpr-g&vendorId=VN00024248&keyword=true&countryCode=US&language=en | O8: CSCC TUNXIS | P8: ='Full Data'!H48 -> 6-144 | Q8: ='Full Data'!H49 -> B- 6 | R8: ='Full Data'!J44 -> g | U8: ='Full Data'!J45 -> 100 | V8: ='Full Data'!J46 -> Keep in a dry, cool and well-ventilated place. Keep container tightly closed. Incompatible Materials. Acids. Strong oxidizing agents. Acid anhydrides. Acid chlorides. Metals.
A9: ='Full Data'!F51 -> 1,1,1-Trichloro-2-methyl-2-propanol hemihydrate | B9: ='Full Data'!J55 -> C4H7Cl3O.0.5H2O | C9: ='Full Data'!F52 -> beta,beta,beta-Trichloro-tert-butyl alcohol | E9: ='Full Data'!F53 -> Eastman Kodak | H9: ='Full Data'!F54 -> 6001-64-5 | I9: ='Full Data'!F55 -> Organic compound | K9: ='Full Data'!F56 -> Warning | L9: ='Full Data'!H51 -> Harmful if swallowed Acute oral toxicity Causes skin irritation Causes serious eye irritation May cause respiratory irritation | M9: ='Full Data'!H53 -> AC, IR | N9: ='Full Data'!H54 -> https://www.fishersci.com/store/msds?partNumber=AAA1018122&productDescription=trichlromethlpr-g&vendorId=VN00024248&keyword=true&countryCode=US&language=en | O9: CSCC TUNXIS | P9: ='Full Data'!H55 -> 6-144 | Q9: ='Full Data'!H56 -> B- 6 | R9: ='Full Data'!J51 -> g | U9: ='Full Data'!J52 -> 100 | V9: ='Full Data'!J53 -> Keep in a dry, cool and well-ventilated place. Keep container tightly closed. Incompatible Materials. Acids. Strong oxidizing agents. Acid anhydrides. Acid chlorides. Metals.
A10: ='Full Data'!F58 -> 1,1,1-Trichloro-2-methyl-2-propanol hemihydrate | B10: ='Full Data'!J62 -> C4H7Cl3O.0.5H2O | C10: ='Full Data'!F59 -> beta,beta,beta-Trichloro-tert-butyl alcohol | E10: ='Full Data'!F60 -> Eastman Kodak | H10: ='Full Data'!F61 -> 6001-64-5 | I10: ='Full Data'!F62 -> Organic compound | K10: ='Full Data'!F63 -> Warning | L10: ='Full Data'!H58 -> Harmful if swallowed Acute oral toxicity Causes skin irritation Causes serious eye irritation May cause respiratory irritation | M10: ='Full Data'!H60 -> AC, IR | N10: ='Full Data'!H61 -> https://www.fishersci.com/store/msds?partNumber=AAA1018122&productDescription=trichlromethlpr-g&vendorId=VN00024248&keyword=true&countryCode=US&language=en | O10: CSCC TUNXIS | P10: ='Full Data'!H62 -> 6-144 | Q10: ='Full Data'!H63 -> B- 6 | R10: ='Full Data'!J58 -> g | U10: ='Full Data'!J59 -> 100 | V10: ='Full Data'!J60 -> Keep in a dry, cool and well-ventilated place. Keep container tightly closed. Incompatible Materials. Acids. Strong oxidizing agents. Acid anhydrides. Acid chlorides. Metals.
A11: ='Full Data'!F65 -> 1,1,1-Trichloro-2-methyl-2-propanol hemihydrate | B11: ='Full Data'!J69 -> C4H7Cl3O.0.5H2O | C11: ='Full Data'!F66 -> beta,beta,beta-Trichloro-tert-butyl alcohol | E11: ='Full Data'!F67 -> Eastman Kodak | H11: ='Full Data'!F68 -> 6001-64-5 | I11: ='Full Data'!F69 -> Organic compound | K11: ='Full Data'!F70 -> Warning | L11: ='Full Data'!H65 -> Harmful if swallowed Acute oral toxicity Causes skin irritation Causes serious eye irritation May cause respiratory irritation | M11: ='Full Data'!H67 -> AC, IR | N11: ='Full Data'!H68 -> https://www.fishersci.com/store/msds?partNumber=AAA1018122&productDescription=trichlromethlpr-g&vendorId=VN00024248&keyword=true&countryCode=US&language=en | O11: CSCC TUNXIS | P11: ='Full Data'!H69 -> 6-144 | Q11: ='Full Data'!H70 -> B- 6 | R11: ='Full Data'!J65 -> g | U11: ='Full Data'!J66 -> 100 | V11: ='Full Data'!J67 -> Keep in a dry, cool and well-ventilated place. Keep container tightly closed. Incompatible Materials. Acids. Strong oxidizing agents. Acid anhydrides. Acid chlorides. Metals.
A12: ='Full Data'!F72 -> (2-Bromoethyl)cyclohexane | B12: ='Full Data'!J76 -> C8H15Br | C12: ='Full Data'!F73 -> Methylchloroform Chlorothene Methyl chloroform Inhibisol Cleanite | E12: ='Full Data'!F74 -> Mallinckrodt | H12: ='Full Data'!F75 -> 1647-26-3 | I12: ='Full Data'!F76 -> Solvent | K12: ='Full Data'!F77 -> Warning | L12: ='Full Data'!H72 -> Causes skin irritation Causes serious eye irritation Skin Corrosion/Irritation May cause respiratory irritation | M12: ='Full Data'!H74 -> IR, CO | N12: ='Full Data'!H75 -> https://www.fishersci.com/store/msds?partNumber=AAL0946606&productDescription=brmoethl-cyclohxane-g&vendorId=VN00024248&keyword=true&countryCode=US&language=en | O12: CSCC TUNXIS | P12: ='Full Data'!H76 -> 6-144 | Q12: ='Full Data'!H77 -> B- 6 | R12: ='Full Data'!J72 -> kg | U12: ='Full Data'!J73 -> 1 | V12: ='Full Data'!J74 -> Keep in a dry, cool and well-ventilated place. Keep container tightly closed. Keep away from heat, sparks and flame. Incompatible Materials. Strong oxidizing agents. Strong bases.
A13: ='Full Data'!F79 -> Ethylene glycol dimethyl ether | B13: ='Full Data'!J83 -> C4H10O2 | C13: ='Full Data'!F80 -> Monoglyme 1,2-Dimethoxyethane | E13: ='Full Data'!F81 -> Fisher | H13: ='Full Data'!F82 -> 110-71-4 | I13: ='Full Data'!F83 -> Organic compound | K13: ='Full Data'!F84 -> Danger | L13: ='Full Data'!H79 -> Highly flammable liquid and vapor Causes skin irritation Causes serious eye irritation Harmful if inhaled May damage fertility. May damage the unborn child | M13: ='Full Data'!H81 -> FL, IR | N13: ='Full Data'!H82 -> https://www.fishersci.com/store/msds?partNumber=AC118450010&productDescription=ethylene-glycol-dimethyl-ml&vendorId=VN00032119&keyword=true&countryCode=US&language=en | O13: CSCC TUNXIS | P13: ='Full Data'!H83 -> 6-147 | Q13: ='Full Data'!H84 -> Flamm. Cab. (S1) | R13: ='Full Data'!J79 -> mL | U13: ='Full Data'!J80 -> 300 | V13: ='Full Data'!J81 -> Keep containers tightly closed in a dry, cool and well-ventilated place. Containers should be dated when opened and tested periodically for the presence of peroxides. Should crystals form in a peroxidizable liquid, peroxidation may have occurred and the product should be considered extremely dangerous. In this instance, the container should only be opened remotely by professionals. Keep away from heat, sparks and flame. Incompatible Materials. Strong oxidizing agents.
A14: ='Full Data'!F86 -> 1,4-Dichlorobenzene | B14: ='Full Data'!J90 -> C6H4Cl2 | C14: ='Full Data'!F87 -> p-Dichlorobenzene | E14: ='Full Data'!F88 -> Acros | H14: ='Full Data'!F89 -> 106-46-7 | I14: ='Full Data'!F90 -> Organic compound | K14: ='Full Data'!F91 -> Danger | L14: ='Full Data'!H86 -> Causes serious eye irritation May cause cancer | M14: ='Full Data'!H88 -> IR, CA | N14: ='Full Data'!H89 -> https://www.fishersci.com/store/msds?partNumber=AC113190010&productDescription=-dichlorobenzene-kg&vendorId=VN00032119&keyword=true&countryCode=US&language=en | O14: CSCC TUNXIS | P14: ='Full Data'!H90 -> 6-144 | Q14: ='Full Data'!H91 -> B-4 | R14: ='Full Data'!J86 -> g | U14: ='Full Data'!J87 -> 300 | V14: ='Full Data'!J88 -> Keep away from heat, sparks and flame. Keep containers tightly closed in a dry, cool and well-ventilated place. Incompatible Materials. Metals.
A15: ='Full Data'!F93 -> 1,4-Dimethoxybenzene | B15: ='Full Data'!J97 -> C8H10O2 | C15: ='Full Data'!F94 -> Hydroquinone dimethyl ether | E15: ='Full Data'!F95 -> Acros | H15: ='Full Data'!F96 -> 150-78-7 | I15: ='Full Data'!F97 -> Organic compound | K15: ='Full Data'!F98 -> Warning | L15: ='Full Data'!H93 -> Causes skin irritation Causes serious eye irritation May cause respiratory irritation | M15: ='Full Data'!H95 -> IR | N15: ='Full Data'!H96 -> https://www.fishersci.com/store/msds?partNumber=AC115410010&productDescription=-dimethoxybenzene--gr&vendorId=VN00032119&keyword=true&countryCode=US&language=en | O15: CSCC TUNXIS | P15: ='Full Data'!H97 -> 6-144 | Q15: ='Full Data'!H98 -> B-4 | R15: ='Full Data'!J93 -> g | U15: ='Full Data'!J94 -> 400 | V15: ='Full Data'!J95 -> Keep in a dry, cool and well-ventilated place. Keep container tightly closed. Incompatible Materials. Strong oxidizing agents.
A16: ='Full Data'!F100 -> 1,4-Dioxane | B16: ='Full Data'!J104 -> C4H8O2 | C16: ='Full Data'!F101 -> Diox | D16: r | E16: ='Full Data'!F102 -> Mallinckrodt | H16: ='Full Data'!F103 -> 123-91-1 | I16: ='Full Data'!F104 -> Organic compound | K16: ='Full Data'!F105 -> Danger | L16: ='Full Data'!H100 -> Highly flammable liquid and vapor Causes serious eye irritation May cause respiratory irritation May cause cancer Company Fisher Scientific Company One Reagent Lane Fair Lawn, NJ 07410 Tel: (201) 796-7100 Emergency Telephone Number CHEMTREC Ò , Inside the USA: 800-424-9300 CHEMTREC Ò , Outside the USA: 001-703-527-3887 Serious Eye Damage/Eye Irritation | M16: ='Full Data'!H102 -> FL, IR, CA | N16: ='Full Data'!H103 -> https://www.fishersci.com/store/msds?partNumber=D1114&productDescription=--dioxane-certified-acs-l&vendorId=VN00000001&keyword=true&countryCode=US&language=en | O16: CSCC TUNXIS | P16: ='Full Data'!H104 -> 6-147 | Q16: ='Full Data'!H105 -> Flamm. Cab. (S1) | R16: ='Full Data'!J100 -> mL | U16: ='Full Data'!J101 -> 500 | V16: ='Full Data'!J102 -> Keep containers tightly closed in a dry, cool and well-ventilated place. Store under an inert atmosphere. Flammables area. May form explosive peroxides. Containers should be dated when opened and tested periodically for the presence of peroxides. Should crystals form in a peroxidizable liquid, peroxidation may have occurred and the product should be considered extremely dangerous. In this instance, the container should only be opened remotely by professionals. Keep away from heat, sparks and flame. Protect from moisture. Incompatible Materials. Strong oxidizing agents. Reducing Agent. Halogens.
A17: ='Full Data'!F107 -> 1,6-Hexanediamine | B17: ='Full Data'!J111 -> C6H16N2 | C17: ='Full Data'!F108 -> 1,6-Diaminohexane Hexamethylenediamine | E17: ='Full Data'!F109 -> Kodak | H17: ='Full Data'!F110 -> 124-09-4 | I17: ='Full Data'!F111 -> Solvent | K17: ='Full Data'!F112 -> Danger 0 Acute oral toxicity Category 4 Acute dermal toxicity Category 4 Skin Corrosion/Irritation Category 1 B Serious Eye Damage/Eye Irritation Category 1 Specific target organ toxicity (single exposure) Category 3 Target Organs - Respiratory system. Flammable liquids Category 4 | L17: ='Full Data'!H107 -> Combustible liquid Causes severe skin burns and eye damage May cause respiratory irritation Harmful if swallowed or in contact with skin | M17: ='Full Data'!H109 -> FL, IR | N17: ='Full Data'!H110 -> https://www.fishersci.com/store/msds?partNumber=AC120645000&productDescription=-hexanediamine--gr&vendorId=VN00032119&keyword=true&countryCode=US&language=en | O17: CSCC TUNXIS | P17: ='Full Data'!H111 -> 6-147 | Q17: ='Full Data'!H112 -> Under SE Hood | R17: ='Full Data'!J107 -> kg | U17: ='Full Data'!J108 -> 1 | V17: ='Full Data'!J109 -> Keep containers tightly closed in a dry, cool and well-ventilated place. Keep away from heat, sparks and flame. Corrosives area. Incompatible Materials. Strong oxidizing agents.
A18: ='Full Data'!F114 -> 1-Bromobutane | B18: ='Full Data'!J118 -> C4H9Br | C18: ='Full Data'!F115 -> n-Butyl bromide | E18: ='Full Data'!F116 -> Aldrich | H18: ='Full Data'!F117 -> 109-65-9 | I18: ='Full Data'!F118 -> Organic compound | K18: ='Full Data'!F119 -> Danger | L18: ='Full Data'!H114 -> Highly flammable liquid and vapor Causes skin irritation Causes serious eye irritation | M18: ='Full Data'!H116 -> FL, IR | N18: ='Full Data'!H117 -> https://www.fishersci.com/store/msds?partNumber=AC106770010&productDescription=bromobutane-ml&vendorId=VN00032119&keyword=true&countryCode=US&language=en | O18: CSCC TUNXIS | P18: ='Full Data'!H118 -> 6-147 | Q18: ='Full Data'!H119 -> Flamm. Cab. (S1) | R18: ='Full Data'!J114 -> g | U18: ='Full Data'!J115 -> 50 | V18: ='Full Data'!J116 -> Keep containers tightly closed in a dry, cool and well-ventilated place. Keep away from heat, sparks and flame. Flammables area. Incompatible Materials. Strong oxidizing agents. Strong bases. Metals.
A19: ='Full Data'!F121 -> 1-Butanol (Certified ACS) | B19: ='Full Data'!J125 -> C4H10O | C19: ='Full Data'!F122 -> n-Butanol n-Butyl alcohol, Butan-1-ol | E19: ='Full Data'!F123 -> Fisher | H19: ='Full Data'!F124 -> 71-36-3 | I19: ='Full Data'!F125 -> Organic compound | K19: ='Full Data'!F126 -> Danger | L19: ='Full Data'!H121 -> Flammable liquid and vapor Harmful if swallowed Causes skin irritation Company Fisher Scientific Company One Reagent Lane Fair Lawn, NJ 07410 Tel: (201) 796-7100 Acute oral toxicity Causes serious eye damage May cause respiratory irritation May cause drowsiness or dizziness | M19: ='Full Data'!H123 -> FL, AC, IR | N19: ='Full Data'!H124 -> https://www.fishersci.com/store/msds?partNumber=A399500&productDescription=butanol-certified-acs-l&vendorId=VN00000001&keyword=true&countryCode=US&language=en | O19: CSCC TUNXIS | P19: ='Full Data'!H125 -> 6-147 | Q19: ='Full Data'!H126 -> East Hood | R19: ='Full Data'!J121 -> L | U19: ='Full Data'!J122 -> 4 | V19: ='Full Data'!J123 -> Keep containers tightly closed in a dry, cool and well-ventilated place. Keep away from heat, sparks and flame. Flammables area. Incompatible Materials. Strong oxidizing agents. Reducing Agent. Acid chlorides. copper. Copper alloys. Acid anhydrides.
A20: ='Full Data'!F128 -> 1-Butanol (Certified ACS) | B20: ='Full Data'!J132 -> C4H10O | C20: ='Full Data'!F129 -> n-Butanol n-Butyl alcohol, Butan-1-ol | E20: ='Full Data'!F130 -> Fisher | H20: ='Full Data'!F131 -> 71-36-3 | I20: ='Full Data'!F132 -> Organic compound | K20: ='Full Data'!F133 -> Danger | L20: ='Full Data'!H128 -> Flammable liquid and vapor Harmful if swallowed Causes skin irritation Company Fisher Scientific Company One Reagent Lane Fair Lawn, NJ 07410 Tel: (201) 796-7100 Acute oral toxicity Causes serious eye damage May cause respiratory irritation May cause drowsiness or dizziness | M20: ='Full Data'!H130 -> FL, AC, IR | N20: ='Full Data'!H131 -> https://www.fishersci.com/store/msds?partNumber=A399500&productDescription=butanol-certified-acs-l&vendorId=VN00000001&keyword=true&countryCode=US&language=en | O20: CSCC TUNXIS | P20: ='Full Data'!H132 -> 6-147 | Q20: ='Full Data'!H133 -> East Hood | R20: ='Full Data'!J128 -> L | U20: ='Full Data'!J129 -> 4 | V20: ='Full Data'!J130 -> Keep containers tightly closed in a dry, cool and well-ventilated place. Keep away from heat, sparks and flame. Flammables area. Incompatible Materials. Strong oxidizing agents. Reducing Agent. Acid chlorides. copper. Copper alloys. Acid anhydrides.
A21: ='Full Data'!F135 -> 1-Chloro-2-methylpropane | B21: ='Full Data'!J139 -> C4H9Cl | C21: ='Full Data'!F136 -> Isobutyl chloride Propane, 1-chloro-2-methyl- | E21: ='Full Data'!F137 -> Aldrich | H21: ='Full Data'!F138 -> 513-36-0 | I21: ='Full Data'!F139 -> Organic compound | K21: ='Full Data'!F140 -> Danger | L21: ='Full Data'!H135 -> Highly flammable liquid and vapor Flammable liquids | M21: ='Full Data'!H137 -> FL | N21: ='Full Data'!H138 -> https://www.fishersci.com/store/msds?partNumber=AAL0418118&productDescription=chlromethlpropane-g&vendorId=VN00024248&keyword=true&countryCode=US&language=en | O21: CSCC TUNXIS | P21: ='Full Data'!H139 -> 6-144 | Q21: ='Full Data'!H140 -> Refrig. | R21: ='Full Data'!J135 -> mL | U21: ='Full Data'!J136 -> 350 | V21: ='Full Data'!J137 -> Keep container tightly closed in a dry and well-ventilated place. Keep away from heat, sparks and flame. Incompatible Materials. Strong oxidizing agents.
A22: ='Full Data'!F142 -> 1-Chloroadamantane | B22: ='Full Data'!J146 -> C10H15Cl | C22: ='Full Data'!F143 -> 1-Adamantyl chloride | E22: ='Full Data'!F144 -> Aldrich | H22: ='Full Data'!F145 -> 935-56-8 | I22: ='Full Data'!F146 -> Organic compound | K22: ='Full Data'!F147 -> Warning | L22: ='Full Data'!H142 -> Causes skin irritation Causes serious eye irritation May cause respiratory irritation | M22: ='Full Data'!H144 -> IR | N22: ='Full Data'!H145 -> https://www.fishersci.com/store/msds?partNumber=AC264240100&productDescription=chloroadamantane-gr&vendorId=VN00032119&keyword=true&countryCode=US&language=en | O22: CSCC TUNXIS | P22: ='Full Data'!H146 -> 6-144 | Q22: ='Full Data'!H147 -> B-3 | R22: ='Full Data'!J142 -> g | U22: ='Full Data'!J143 -> 15 | V22: ='Full Data'!J144 -> Keep in a dry, cool and well-ventilated place. Keep container tightly closed. Incompatible Materials. Oxidizing agent.
A23: ='Full Data'!F149 -> n-Butyl chloride | B23: ='Full Data'!J153 -> C4H9Cl | C23: ='Full Data'!F150 -> Butyl chloride N-BUTYL CHLORIDE Butane, 1-chloro- Chlorure de butyle NBC wormer | E23: ='Full Data'!F151 -> Aldrich | H23: ='Full Data'!F152 -> 109-69-3 | I23: ='Full Data'!F153 -> Organic compound | K23: ='Full Data'!F154 -> Danger | L23: ='Full Data'!H149 -> Highly flammable liquid and vapor May be fatal if swallowed and enters airways Company Fisher Scientific Company One Reagent Lane Fair Lawn, NJ 07410 Tel: (201) 796-7100 Aspiration Toxicity | M23: ='Full Data'!H151 -> FL, AC | N23: ='Full Data'!H152 -> https://www.fishersci.com/store/msds?partNumber=B4294&productDescription=nbutyl-chloride-hplc-l-sk&vendorId=VN00000001&keyword=true&countryCode=US&language=en | O23: CSCC TUNXIS | P23: ='Full Data'!H153 -> 6-147 | Q23: ='Full Data'!H154 -> Flamm. Cab. (S1) | R23: ='Full Data'!J149 -> L | U23: ='Full Data'!J150 -> 1 | V23: ='Full Data'!J151 -> Keep containers tightly closed in a dry, cool and well-ventilated place. Flammables area. Keep away from heat, sparks and flame. Incompatible Materials. Strong oxidizing agents. Strong bases.
A24: ='Full Data'!F156 -> 1-Naphthol | B24: ='Full Data'!J160 -> C10H8O | C24: ='Full Data'!F157 -> 1-Hydroxynaphthalene | E24: ='Full Data'!F158 -> Acros | H24: ='Full Data'!F159 -> 90-15-3 | I24: ='Full Data'!F160 -> Organic compound | K24: ='Full Data'!F161 -> Danger | L24: ='Full Data'!H156 -> Acute oral toxicity Causes skin irritation Causes serious eye damage May cause respiratory irritation Harmful if swallowed or in contact with skin | M24: ='Full Data'!H158 -> AC, IR | N24: ='Full Data'!H159 -> https://www.fishersci.com/store/msds?partNumber=AAA118620E&productDescription=naphthol-g&vendorId=VN00024248&keyword=true&countryCode=US&language=en | O24: CSCC TUNXIS | P24: ='Full Data'!H160 -> 6-144 | Q24: ='Full Data'!H161 -> B- 5 | R24: ='Full Data'!J156 -> g | U24: ='Full Data'!J157 -> 50 | V24: ='Full Data'!J158 -> Keep in a dry, cool and well-ventilated place. Protect from direct sunlight. Incompatible Materials. Strong oxidizing agents. Strong bases. Halogens. Acid anhydrides. Acid chlorides.
A25: ='Full Data'!F163 -> 1-Naphthol | B25: ='Full Data'!J167 -> C10H8O | C25: ='Full Data'!F164 -> 1-Hydroxynaphthalene | E25: ='Full Data'!F165 -> Acros | H25: ='Full Data'!F166 -> 90-15-3 | I25: ='Full Data'!F167 -> Organic compound | K25: ='Full Data'!F168 -> Danger | L25: ='Full Data'!H163 -> Acute oral toxicity Causes skin irritation Causes serious eye damage May cause respiratory irritation Harmful if swallowed or in contact with skin | M25: ='Full Data'!H165 -> AC, IR | N25: ='Full Data'!H166 -> https://www.fishersci.com/store/msds?partNumber=AAA118620E&productDescription=naphthol-g&vendorId=VN00024248&keyword=true&countryCode=US&language=en | O25: CSCC TUNXIS | P25: ='Full Data'!H167 -> 6-144 | Q25: ='Full Data'!H168 -> B- 5 | R25: ='Full Data'!J163 -> g | U25: ='Full Data'!J164 -> 50 | V25: ='Full Data'!J165 -> Keep in a dry, cool and well-ventilated place. Protect from direct sunlight. Incompatible Materials. Strong oxidizing agents. Strong bases. Halogens. Acid anhydrides. Acid chlorides.
A26: ='Full Data'!F170 -> 1-Propanol | B26: ='Full Data'!J174 -> C3H8O | C26: ='Full Data'!F171 -> n-Propanol n-Propyl alcohol (Certified/Peroxide-Free/Sequencing) | E26: ='Full Data'!F172 -> Baker | H26: ='Full Data'!F173 -> 71-23-8 | I26: ='Full Data'!F174 -> Organic compound | K26: ='Full Data'!F175 -> Danger | L26: ='Full Data'!H170 -> Highly flammable liquid and vapor Causes serious eye damage Company Fisher Scientific Company One Reagent Lane Fair Lawn, NJ 07410 Tel: (201) 796-7100 Emergency Telephone Number CHEMTREC Ò , Inside the USA: 800-424-9300 CHEMTREC Ò , Outside the USA: 001-703-527-3887 Serious Eye Damage/Eye Irritation May cause drowsiness or dizziness | M26: ='Full Data'!H172 -> FL, IR | N26: ='Full Data'!H173 -> https://www.fishersci.com/store/msds?partNumber=A4144&productDescription=propanol-certified-l&vendorId=VN00000001&keyword=true&countryCode=US&language=en | O26: CSCC TUNXIS | P26: ='Full Data'!H174 -> 6-147 | Q26: ='Full Data'!H175 -> Flamm. Cab. (S3) | R26: ='Full Data'!J170 -> L | U26: ='Full Data'!J171 -> 3 | V26: ='Full Data'!J172 -> Keep containers tightly closed in a dry, cool and well-ventilated place. Keep away from heat, sparks and flame. Flammables area. Incompatible Materials. Strong oxidizing agents. Strong acids.
A27: ='Full Data'!F177 -> 2,3,5-Triphenyl-2H-tetrazolium chloride | B27: ='Full Data'!J181 -> C19H15N4Cl | C27: ='Full Data'!F178 -> Red tetrazolium TPTZ TTC | E27: ='Full Data'!F179 -> Sigma | H27: ='Full Data'!F180 -> 298-96-4 | I27: ='Full Data'!F181 -> Organic compound | K27: ='Full Data'!F182 -> Warning | L27: ='Full Data'!H177 -> Causes skin irritation Causes serious eye irritation Skin Corrosion/Irritation May cause respiratory irritation | M27: ='Full Data'!H179 -> IR, CO | N27: ='Full Data'!H180 -> https://www.fishersci.com/store/msds?partNumber=AAA1087009&productDescription=triphenlhtetzolium-g&vendorId=VN00024248&keyword=true&countryCode=US&language=en | O27: CSCC TUNXIS | P27: ='Full Data'!H181 -> 6-144 | Q27: ='Full Data'!H182 -> B- 6 | R27: ='Full Data'!J177 -> g | U27: ='Full Data'!J178 -> 50 | V27: ='Full Data'!J179 -> Protect from light. Store under an inert atmosphere. Keep container tightly closed in a dry and well-ventilated place. Keep refrigerated. Incompatible Materials. Strong oxidizing agents.
A28: ='Full Data'!F184 -> 2,3,5-Triphenyl-2H-tetrazolium chloride | B28: ='Full Data'!J188 -> C19H15N4Cl | C28: ='Full Data'!F185 -> Red tetrazolium TPTZ TTC | E28: ='Full Data'!F186 -> Sigma | H28: ='Full Data'!F187 -> 298-96-4 | I28: ='Full Data'!F188 -> Organic compound | K28: ='Full Data'!F189 -> Warning | L28: ='Full Data'!H184 -> Causes skin irritation Causes serious eye irritation Skin Corrosion/Irritation May cause respiratory irritation | M28: ='Full Data'!H186 -> IR, CO | N28: ='Full Data'!H187 -> https://www.fishersci.com/store/msds?partNumber=AAA1087009&productDescription=triphenlhtetzolium-g&vendorId=VN00024248&keyword=true&countryCode=US&language=en | O28: CSCC TUNXIS | P28: ='Full Data'!H188 -> 6-144 | Q28: ='Full Data'!H189 -> B- 6 | R28: ='Full Data'!J184 -> g | U28: ='Full Data'!J185 -> 50 | V28: ='Full Data'!J186 -> Protect from light. Store under an inert atmosphere. Keep container tightly closed in a dry and well-ventilated place. Keep refrigerated. Incompatible Materials. Strong oxidizing agents.
A29: ='Full Data'!F191 -> Glycidyl 2-methylphenyl ether | B29: ='Full Data'!J195 -> C10H12O2 | C29: ='Full Data'!F192 -> No information available | E29: ='Full Data'!F193 -> Acros | H29: ='Full Data'!F194 -> 2210-79-9 | I29: ='Full Data'!F195 -> Organic compound | K29: ='Full Data'!F196 -> Danger | L29: ='Full Data'!H191 -> Causes skin irritation Acute Inhalation Toxicity - Vapors Causes serious eye irritation Toxic if inhaled May cause allergy or asthma symptoms or breathing difficulties if inhaled Suspected of causing genetic defects | M29: ='Full Data'!H193 -> AC, IR | N29: ='Full Data'!H194 -> https://www.fishersci.com/store/msds?partNumber=AAL1013622&productDescription=glycidyl-methlphenl-eth-g&vendorId=VN00024248&keyword=true&countryCode=US&language=en | O29: CSCC TUNXIS | P29: ='Full Data'!H195 -> 6-144 | Q29: ='Full Data'!H196 -> B-4 | R29: ='Full Data'!J191 -> g | U29: ='Full Data'!J192 -> 20 | V29: ='Full Data'!J193 -> Keep containers tightly closed in a dry, cool and well-ventilated place. Incompatible Materials. Oxidizing agent.
A30: ='Full Data'!F198 -> 2,6-Dichloroindophenol sodium salt hydrate | B30: ='Full Data'!J202 -> C12H6Cl2NNaO2.xH2O | C30: ='Full Data'!F199 -> 2,6-Dichlorophenolindophenol sodium salt hydrate Tillman`s reagent hydrate 2,6-Dichloro-N-(4-hydroxyphenyl)-1,4-benzoquinoneime sodium salt DCIP DPIP | E30: ='Full Data'!F200 -> Mallinckrodt | H30: ='Full Data'!F201 -> 1266615-56-8 | I30: ='Full Data'!F202 -> Inorganic salt | K30: ='Full Data'!F203 -> Warning | L30: ='Full Data'!H198 -> May form combustible dust concentrations in air | M30: ='Full Data'!H200 -> FL | N30: ='Full Data'!H201 -> https://www.fishersci.com/store/msds?partNumber=AAA1010722&productDescription=dichlroindophenol-sod-g&vendorId=VN00024248&keyword=true&countryCode=US&language=en | O30: CSCC TUNXIS | P30: ='Full Data'!H202 -> 6-144 | Q30: ='Full Data'!H203 -> B-4 | R30: ='Full Data'!J198 -> g | U30: ='Full Data'!J199 -> 1 | V30: ='Full Data'!J200 -> Keep in a dry, cool and well-ventilated place. Keep container tightly closed. Keep container tightly closed in a dry and well-ventilated place. Protect from moisture. Store under an inert atmosphere. Incompatible Materials. Strong oxidizing agents.
A31: ='Full Data'!F205 -> 2,6-Dichloroindophenol sodium salt hydrate | B31: ='Full Data'!J209 -> C12H6Cl2NNaO2.xH2O | C31: ='Full Data'!F206 -> 2,6-Dichlorophenolindophenol sodium salt hydrate Tillman`s reagent hydrate 2,6-Dichloro-N-(4-hydroxyphenyl)-1,4-benzoquinoneime sodium salt DCIP DPIP | E31: ='Full Data'!F207 -> Mallinckrodt | H31: ='Full Data'!F208 -> 1266615-56-8 | I31: ='Full Data'!F209 -> Inorganic salt | K31: ='Full Data'!F210 -> Warning | L31: ='Full Data'!H205 -> May form combustible dust concentrations in air | M31: ='Full Data'!H207 -> FL | N31: ='Full Data'!H208 -> https://www.fishersci.com/store/msds?partNumber=AAA1010722&productDescription=dichlroindophenol-sod-g&vendorId=VN00024248&keyword=true&countryCode=US&language=en | O31: CSCC TUNXIS | P31: ='Full Data'!H209 -> 6-144 | Q31: ='Full Data'!H210 -> B-4 | R31: ='Full Data'!J205 -> g | U31: ='Full Data'!J206 -> 1 | V31: ='Full Data'!J207 -> Keep in a dry, cool and well-ventilated place. Keep container tightly closed. Keep container tightly closed in a dry and well-ventilated place. Protect from moisture. Store under an inert atmosphere. Incompatible Materials. Strong oxidizing agents.
A32: ='Full Data'!F212 -> 2-Amino-6-methoxybenzothiazole | B32: ='Full Data'!J216 -> C8H8N2OS | C32: ='Full Data'!F213 -> 6-Methoxy-2-aminobenzothiazole | E32: ='Full Data'!F214 -> Acros | H32: ='Full Data'!F215 -> 1747-60-0 | I32: ='Full Data'!F216 -> Organic compound | K32: ='Full Data'!F217 -> Danger | L32: ='Full Data'!H212 -> Toxic if swallowed Suspected of causing genetic defects | M32: ='Full Data'!H214 -> AC | N32: ='Full Data'!H215 -> https://www.fishersci.com/store/msds?partNumber=AC172020500&productDescription=aminomethoxybenzothi-gr&vendorId=VN00032119&keyword=true&countryCode=US&language=en | O32: CSCC TUNXIS | P32: ='Full Data'!H216 -> 6-144 | Q32: ='Full Data'!H217 -> B-3 | R32: ='Full Data'!J212 -> g | U32: ='Full Data'!J213 -> 50 | V32: ='Full Data'!J214 -> Keep in a dry, cool and well-ventilated place. Keep container tightly closed. Incompatible Materials. Strong oxidizing agents.
A33: ='Full Data'!F219 -> 2-Bromobutane | B33: ='Full Data'!J223 -> C4H9Br | C33: ='Full Data'!F220 -> sec-Butyl bromide | E33: ='Full Data'!F221 -> Aldrich | H33: ='Full Data'!F222 -> 78-76-2 | I33: ='Full Data'!F223 -> Organic compound | K33: ='Full Data'!F224 -> Danger | L33: ='Full Data'!H219 -> May be corrosive to metals Causes severe skin burns and eye damage May cause respiratory irritation | M33: ='Full Data'!H221 -> CO, IR | N33: ='Full Data'!H222 -> https://www.fishersci.com/store/msds?partNumber=AC106785000&productDescription=bromobutane-ml&vendorId=VN00032119&keyword=true&countryCode=US&language=en | O33: CSCC TUNXIS | P33: ='Full Data'!H223 -> 6-147 | Q33: ='Full Data'!H224 -> Flamm. Cab. (S1) | R33: ='Full Data'!J219 -> g | U33: ='Full Data'!J220 -> 100 | V33: ='Full Data'!J221 -> Keep in a dry, cool and well-ventilated place. Keep container tightly closed. Keep away from heat, sparks and flame. Flammables area. Corrosives area. Keep containers tightly closed in a dry, cool and well-ventilated place. Incompatible Materials. Strong oxidizing agents. Strong bases. Metals.
A34: ='Full Data'!F226 -> Methyl Ethyl Ketone | B34: ='Full Data'!J230 -> C4H8O | C34: ='Full Data'!F227 -> 2-Butanone MEK Ethyl methyl ketone | E34: ='Full Data'!F228 -> Kodak | H34: ='Full Data'!F229 -> 78-93-3 | I34: ='Full Data'!F230 -> Organic compound | K34: ='Full Data'!F231 -> Danger Company Fisher Scientific Company One Reagent Lane Fair Lawn, NJ 07410 Tel: (201) 796-7100 Serious Eye Damage/Eye Irritation Category 2 Specific target organ toxicity (single exposure) Category 3 Target Organs - Central nervous system (CNS). Specific target organ toxicity - (repeated exposure) Category 2 Target Organs - Kidney, Liver. Flammable liquids Category 2 | L34: ='Full Data'!H226 -> Highly flammable liquid and vapor Causes serious eye irritation May cause drowsiness or dizziness May cause damage to organs through prolonged or repeated exposure | M34: ='Full Data'!H228 -> FL, IR | N34: ='Full Data'!H229 -> https://www.fishersci.com/store/msds?partNumber=M2094&productDescription=methyl-ethyl-ketone-cert-l&vendorId=VN00000001&keyword=true&countryCode=US&language=en | O34: CSCC TUNXIS | P34: ='Full Data'!H230 -> 6-147 | Q34: ='Full Data'!H231 -> Flamm. Cab. (S1) | R34: ='Full Data'!J226 -> kg | U34: ='Full Data'!J227 -> 1 | V34: ='Full Data'!J228 -> Keep containers tightly closed in a dry, cool and well-ventilated place. Keep away from heat, sparks and flame. Flammables area. Incompatible Materials. Strong oxidizing agents. Strong acids. Strong bases. Strong reducing agents. Ammonia. copper. Amines.
A35: ='Full Data'!F233 -> 2-Chloro-2-methylpropane | B35: ='Full Data'!J237 -> C4H9Cl | C35: ='Full Data'!F234 -> tert-Butyl chloride | E35: ='Full Data'!F235 -> Acros | H35: ='Full Data'!F236 -> 507-20-0 | I35: ='Full Data'!F237 -> Organic compound | K35: ='Full Data'!F238 -> Danger | L35: ='Full Data'!H233 -> Highly flammable liquid and vapor | M35: ='Full Data'!H235 -> FL | N35: ='Full Data'!H236 -> https://www.fishersci.com/store/msds?partNumber=AC109505000&productDescription=chloromethylpropane-ml&vendorId=VN00032119&keyword=true&countryCode=US&language=en | O35: CSCC TUNXIS | P35: ='Full Data'!H237 -> 6-147 | Q35: ='Full Data'!H238 -> Flamm. Cab. (S1) | R35: ='Full Data'!J233 -> mL | U35: ='Full Data'!J234 -> 300 | V35: ='Full Data'!J235 -> Keep away from heat, sparks and flame. Keep container tightly closed in a dry and well-ventilated place. Incompatible Materials. Strong oxidizing agents.
A36: ='Full Data'!F240 -> 2-Chlorobutane | B36: ='Full Data'!J244 -> C4H9Cl | C36: ='Full Data'!F241 -> sec-Butyl chloride | E36: ='Full Data'!F242 -> Aldrich | H36: ='Full Data'!F243 -> 78-86-4 | I36: ='Full Data'!F244 -> Organic compound | K36: ='Full Data'!F245 -> Danger | L36: ='Full Data'!H240 -> Highly flammable liquid and vapor May be corrosive to metals | M36: ='Full Data'!H242 -> FL, CO | N36: ='Full Data'!H243 -> https://www.fishersci.com/store/msds?partNumber=AC108832500&productDescription=chlorobutane-ml&vendorId=VN00032119&keyword=true&countryCode=US&language=en | O36: CSCC TUNXIS | P36: ='Full Data'!H244 -> 6-147 | Q36: ='Full Data'!H245 -> Flamm. Cab. (S1) | R36: ='Full Data'!J240 -> mL | U36: ='Full Data'!J241 -> 200 | V36: ='Full Data'!J242 -> Flammables area. Keep away from heat/sparks/open flames/hot surfaces. - No smoking. Keep container tightly closed in a dry and well-ventilated place. Keep away from heat, sparks and flame. Keep under nitrogen. Incompatible Materials. Strong oxidizing agents. Strong bases. Metals. copper. Strong acids.
A37: ='Full Data'!F247 -> 2-Furaldehyde | B37: ='Full Data'!J251 -> C5H4O2 | C37: ='Full Data'!F248 -> Furfural 2-Furancarboxaldehyde | E37: ='Full Data'!F249 -> Acros | H37: ='Full Data'!F250 -> 98-01-1 | I37: ='Full Data'!F251 -> Organic compound | K37: ='Full Data'!F252 -> Danger Acute oral toxicity Category 3 Acute dermal toxicity Category 4 Acute Inhalation Toxicity - Dusts and Mists Category 2 Skin Corrosion/Irritation Category 2 Serious Eye Damage/Eye Irritation Category 2 Specific target organ toxicity (single exposure) Category 3 Target Organs - Respiratory system. Specific target organ toxicity - (repeated exposure) Category 2 Target Organs - Kidney, Liver, spleen. Flammable liquids Category 3 | L37: ='Full Data'!H247 -> Flammable liquid and vapor Toxic if swallowed Harmful in contact with skin Fatal if inhaled Causes skin irritation Causes serious eye irritation May cause respiratory irritation May cause damage to organs through prolonged or repeated exposure | M37: ='Full Data'!H249 -> FL, AC, IR | N37: ='Full Data'!H250 -> https://www.fishersci.com/store/msds?partNumber=AAA161670B&productDescription=furaldehyde-g&vendorId=VN00024248&keyword=true&countryCode=US&language=en | O37: CSCC TUNXIS | P37: ='Full Data'!H251 -> 6-144 | Q37: ='Full Data'!H252 -> B-4 | R37: ='Full Data'!J247 -> mL | U37: ='Full Data'!J248 -> 250 | V37: ='Full Data'!J249 -> Keep away from heat, sparks and flame. Keep containers tightly closed in a dry, cool and well-ventilated place. Incompatible Materials. Strong oxidizing agents. Strong bases. Strong acids.
A38: ='Full Data'!F254 -> 2-Furaldehyde | B38: ='Full Data'!J258 -> C5H4O2 | C38: ='Full Data'!F255 -> Furfural 2-Furancarboxaldehyde | E38: ='Full Data'!F256 -> Acros | H38: ='Full Data'!F257 -> 98-01-1 | I38: ='Full Data'!F258 -> Organic compound | K38: ='Full Data'!F259 -> Danger Acute oral toxicity Category 3 Acute dermal toxicity Category 4 Acute Inhalation Toxicity - Dusts and Mists Category 2 Skin Corrosion/Irritation Category 2 Serious Eye Damage/Eye Irritation Category 2 Specific target organ toxicity (single exposure) Category 3 Target Organs - Respiratory system. Specific target organ toxicity - (repeated exposure) Category 2 Target Organs - Kidney, Liver, spleen. Flammable liquids Category 3 | L38: ='Full Data'!H254 -> Flammable liquid and vapor Toxic if swallowed Harmful in contact with skin Fatal if inhaled Causes skin irritation Causes serious eye irritation May cause respiratory irritation May cause damage to organs through prolonged or repeated exposure | M38: ='Full Data'!H256 -> FL, AC, IR | N38: ='Full Data'!H257 -> https://www.fishersci.com/store/msds?partNumber=AAA161670B&productDescription=furaldehyde-g&vendorId=VN00024248&keyword=true&countryCode=US&language=en | O38: CSCC TUNXIS | P38: ='Full Data'!H258 -> 6-144 | Q38: ='Full Data'!H259 -> B-4 | R38: ='Full Data'!J254 -> mL | U38: ='Full Data'!J255 -> 250 | V38: ='Full Data'!J256 -> Keep away from heat, sparks and flame. Keep containers tightly closed in a dry, cool and well-ventilated place. Incompatible Materials. Strong oxidizing agents. Strong bases. Strong acids.
A39: ='Full Data'!F261 -> 2-Heptanone | B39: ='Full Data'!J265 -> C7H14O | C39: ='Full Data'!F262 -> Methyl amyl ketone | E39: ='Full Data'!F263 -> Acros | H39: ='Full Data'!F264 -> 110-43-0 | I39: ='Full Data'!F265 -> Organic compound | K39: ='Full Data'!F266 -> Warning | L39: ='Full Data'!H261 -> Flammable liquid and vapor May cause drowsiness or dizziness Harmful if swallowed or if inhaled Acute oral toxicity | M39: ='Full Data'!H263 -> FL, AC | N39: ='Full Data'!H264 -> https://www.fishersci.com/store/msds?partNumber=AAA10200AP&productDescription=heptanone-ml&vendorId=VN00024248&keyword=true&countryCode=US&language=en | O39: CSCC TUNXIS | P39: ='Full Data'!H265 -> 6-144 | Q39: ='Full Data'!H266 -> B-4 | R39: ='Full Data'!J261 -> mL | U39: ='Full Data'!J262 -> 115 | V39: ='Full Data'!J263 -> Keep containers tightly closed in a dry, cool and well-ventilated place. Keep away from heat, sparks and flame. Flammables area. Incompatible Materials. Strong oxidizing Health 2 Flammability 2 Instability 0 Physical hazards N/A agents.
